[2022-03-21 03:43:10,192] {taskinstance.py:851} INFO - Dependencies all met for <TaskInstance: 311_service_request_dag.upload_to_gcs_job 2022-03-21T03:42:29.292959+00:00 [queued]>
[2022-03-21 03:43:10,231] {taskinstance.py:851} INFO - Dependencies all met for <TaskInstance: 311_service_request_dag.upload_to_gcs_job 2022-03-21T03:42:29.292959+00:00 [queued]>
[2022-03-21 03:43:10,232] {taskinstance.py:1042} INFO - 
--------------------------------------------------------------------------------
[2022-03-21 03:43:10,234] {taskinstance.py:1043} INFO - Starting attempt 1 of 1
[2022-03-21 03:43:10,235] {taskinstance.py:1044} INFO - 
--------------------------------------------------------------------------------
[2022-03-21 03:43:10,260] {taskinstance.py:1063} INFO - Executing <Task(PythonOperator): upload_to_gcs_job> on 2022-03-21T03:42:29.292959+00:00
[2022-03-21 03:43:10,269] {standard_task_runner.py:52} INFO - Started process 27341 to run task
[2022-03-21 03:43:10,278] {standard_task_runner.py:76} INFO - Running: ['airflow', 'tasks', 'run', '311_service_request_dag', 'upload_to_gcs_job', '2022-03-21T03:42:29.292959+00:00', '--job-id', '90', '--pool', 'default_pool', '--raw', '--subdir', 'DAGS_FOLDER/311_download_ingest_gcs.py', '--cfg-path', '/tmp/tmp2o70a8g2', '--error-file', '/tmp/tmpelij6vzg']
[2022-03-21 03:43:10,285] {standard_task_runner.py:77} INFO - Job 90: Subtask upload_to_gcs_job
[2022-03-21 03:43:10,367] {logging_mixin.py:104} INFO - Running <TaskInstance: 311_service_request_dag.upload_to_gcs_job 2022-03-21T03:42:29.292959+00:00 [running]> on host 0e06240adef1
[2022-03-21 03:43:10,460] {taskinstance.py:1257} INFO - Exporting the following env vars:
AIRFLOW_CTX_DAG_OWNER=airflow
AIRFLOW_CTX_DAG_ID=311_service_request_dag
AIRFLOW_CTX_TASK_ID=upload_to_gcs_job
AIRFLOW_CTX_EXECUTION_DATE=2022-03-21T03:42:29.292959+00:00
AIRFLOW_CTX_DAG_RUN_ID=manual__2022-03-21T03:42:29.292959+00:00
[2022-03-21 03:43:10,576] {taskinstance.py:1455} ERROR - [Errno 21] Is a directory: '/opt/airflow'
Traceback (most recent call last):
  File "/home/airflow/.local/lib/python3.6/site-packages/airflow/models/taskinstance.py", line 1112, in _run_raw_task
    self._prepare_and_execute_task_with_callbacks(context, task)
  File "/home/airflow/.local/lib/python3.6/site-packages/airflow/models/taskinstance.py", line 1285, in _prepare_and_execute_task_with_callbacks
    result = self._execute_task(context, task_copy)
  File "/home/airflow/.local/lib/python3.6/site-packages/airflow/models/taskinstance.py", line 1315, in _execute_task
    result = task_copy.execute(context=context)
  File "/home/airflow/.local/lib/python3.6/site-packages/airflow/operators/python.py", line 117, in execute
    return_value = self.execute_callable()
  File "/home/airflow/.local/lib/python3.6/site-packages/airflow/operators/python.py", line 128, in execute_callable
    return self.python_callable(*self.op_args, **self.op_kwargs)
  File "/opt/airflow/dags/311_download_ingest_gcs.py", line 53, in upload_to_gcs
    blob.upload_from_filename(local_file)
  File "/home/airflow/.local/lib/python3.6/site-packages/google/cloud/storage/blob.py", line 2473, in upload_from_filename
    with open(filename, "rb") as file_obj:
IsADirectoryError: [Errno 21] Is a directory: '/opt/airflow'
[2022-03-21 03:43:10,590] {taskinstance.py:1503} INFO - Marking task as FAILED. dag_id=311_service_request_dag, task_id=upload_to_gcs_job, execution_date=20220321T034229, start_date=20220321T034310, end_date=20220321T034310
[2022-03-21 03:43:10,661] {local_task_job.py:146} INFO - Task exited with return code 1
