[2022-03-19 18:11:56,320] {taskinstance.py:851} INFO - Dependencies all met for <TaskInstance: 311_service_request_dag.upload_to_gcs_job 2022-03-17T13:29:34.380568+00:00 [queued]>
[2022-03-19 18:11:56,350] {taskinstance.py:851} INFO - Dependencies all met for <TaskInstance: 311_service_request_dag.upload_to_gcs_job 2022-03-17T13:29:34.380568+00:00 [queued]>
[2022-03-19 18:11:56,351] {taskinstance.py:1042} INFO - 
--------------------------------------------------------------------------------
[2022-03-19 18:11:56,352] {taskinstance.py:1043} INFO - Starting attempt 4 of 4
[2022-03-19 18:11:56,354] {taskinstance.py:1044} INFO - 
--------------------------------------------------------------------------------
[2022-03-19 18:11:56,384] {taskinstance.py:1063} INFO - Executing <Task(PythonOperator): upload_to_gcs_job> on 2022-03-17T13:29:34.380568+00:00
[2022-03-19 18:11:56,392] {standard_task_runner.py:52} INFO - Started process 387 to run task
[2022-03-19 18:11:56,402] {standard_task_runner.py:76} INFO - Running: ['airflow', 'tasks', 'run', '311_service_request_dag', 'upload_to_gcs_job', '2022-03-17T13:29:34.380568+00:00', '--job-id', '76', '--pool', 'default_pool', '--raw', '--subdir', 'DAGS_FOLDER/311_download_ingest_gcs.py', '--cfg-path', '/tmp/tmp1refpjbv', '--error-file', '/tmp/tmp8i4pdz_j']
[2022-03-19 18:11:56,408] {standard_task_runner.py:77} INFO - Job 76: Subtask upload_to_gcs_job
[2022-03-19 18:11:56,489] {logging_mixin.py:104} INFO - Running <TaskInstance: 311_service_request_dag.upload_to_gcs_job 2022-03-17T13:29:34.380568+00:00 [running]> on host 3278a52a4586
[2022-03-19 18:11:56,592] {taskinstance.py:1257} INFO - Exporting the following env vars:
AIRFLOW_CTX_DAG_OWNER=airflow
AIRFLOW_CTX_DAG_ID=311_service_request_dag
AIRFLOW_CTX_TASK_ID=upload_to_gcs_job
AIRFLOW_CTX_EXECUTION_DATE=2022-03-17T13:29:34.380568+00:00
AIRFLOW_CTX_DAG_RUN_ID=manual__2022-03-17T13:29:34.380568+00:00
[2022-03-19 18:11:56,703] {taskinstance.py:1455} ERROR - [Errno 2] No such file or directory: '/opt/airflow/311request_2022_03_17-01_29_34_PM.parquet'
Traceback (most recent call last):
  File "/home/airflow/.local/lib/python3.6/site-packages/airflow/models/taskinstance.py", line 1112, in _run_raw_task
    self._prepare_and_execute_task_with_callbacks(context, task)
  File "/home/airflow/.local/lib/python3.6/site-packages/airflow/models/taskinstance.py", line 1285, in _prepare_and_execute_task_with_callbacks
    result = self._execute_task(context, task_copy)
  File "/home/airflow/.local/lib/python3.6/site-packages/airflow/models/taskinstance.py", line 1315, in _execute_task
    result = task_copy.execute(context=context)
  File "/home/airflow/.local/lib/python3.6/site-packages/airflow/operators/python.py", line 117, in execute
    return_value = self.execute_callable()
  File "/home/airflow/.local/lib/python3.6/site-packages/airflow/operators/python.py", line 128, in execute_callable
    return self.python_callable(*self.op_args, **self.op_kwargs)
  File "/opt/airflow/dags/311_download_ingest_gcs.py", line 53, in upload_to_gcs
    blob.upload_from_filename(local_file)
  File "/home/airflow/.local/lib/python3.6/site-packages/google/cloud/storage/blob.py", line 2473, in upload_from_filename
    with open(filename, "rb") as file_obj:
FileNotFoundError: [Errno 2] No such file or directory: '/opt/airflow/311request_2022_03_17-01_29_34_PM.parquet'
[2022-03-19 18:11:56,716] {taskinstance.py:1503} INFO - Marking task as FAILED. dag_id=311_service_request_dag, task_id=upload_to_gcs_job, execution_date=20220317T132934, start_date=20220319T181156, end_date=20220319T181156
[2022-03-19 18:11:56,782] {local_task_job.py:146} INFO - Task exited with return code 1
